format': {'type': 'json_object'}}}
[2025-02-08 08:41:52,254] DEBUG in _base_client: Sending HTTP Request: POST https://api.openai.com/v1/chat/completions
[2025-02-08 08:41:52,254] DEBUG in _trace: send_request_headers.started request=<Request [b'POST']>
[2025-02-08 08:41:52,254] DEBUG in _trace: send_request_headers.complete
[2025-02-08 08:41:52,255] DEBUG in _trace: send_request_body.started request=<Request [b'POST']>
[2025-02-08 08:41:52,553] DEBUG in _trace: send_request_body.complete
[2025-02-08 08:41:52,553] DEBUG in _trace: receive_response_headers.started request=<Request [b'POST']>
[2025-02-08 08:41:56,490] DEBUG in _trace: receive_response_headers.complete return_value=(b'HTTP/1.1', 200, b'OK', [(b'Date', b'Sat, 08 Feb 2025 08:41:56 GMT'), (b'Content-Type', b'application/json'), (b'Transfer-Encoding', b'chunked'), (b'Connection', b'keep-alive'), (b'access-control-expose-headers', b'X-Request-ID'), (b'openai-organization', b'user-r8fvvzrst5hfap7jphqbxk6c'), (b'openai-processing-ms', b'2423'), (b'openai-version', b'2020-10-01'), (b'x-ratelimit-limit-input-images', b'50000'), (b'x-ratelimit-limit-requests', b'5000'), (b'x-ratelimit-limit-tokens', b'800000'), (b'x-ratelimit-remaining-input-images', b'49999'), (b'x-ratelimit-remaining-requests', b'4999'), (b'x-ratelimit-remaining-tokens', b'798754'), (b'x-ratelimit-reset-input-images', b'1ms'), (b'x-ratelimit-reset-requests', b'12ms'), (b'x-ratelimit-reset-tokens', b'93ms'), (b'x-request-id', b'req_f06eb55fb3fcd3a5c0410accfa3a3f6c'), (b'strict-transport-security', b'max-age=31536000; includeSubDomains; preload'), (b'CF-Cache-Status', b'DYNAMIC'), (b'X-Content-Type-Options', b'nosniff'), (b'Server', b'cloudflare'), (b'CF-RAY', b'90ea52b5af3253f1-ATL'), (b'Content-Encoding', b'gzip'), (b'alt-svc', b'h3=":443"; ma=86400')])
[2025-02-08 08:41:56,491] INFO in _client: HTTP Request: POST https://api.openai.com/v1/chat/completions "HTTP/1.1 200 OK"
[2025-02-08 08:41:56,491] DEBUG in _trace: receive_response_body.started request=<Request [b'POST']>
[2025-02-08 08:41:56,491] DEBUG in _trace: receive_response_body.complete
[2025-02-08 08:41:56,491] DEBUG in _trace: response_closed.started
[2025-02-08 08:41:56,491] DEBUG in _trace: response_closed.complete
[2025-02-08 08:41:56,491] DEBUG in _base_client: HTTP Response: POST https://api.openai.com/v1/chat/completions "200 OK" Headers({'date': 'Sat, 08 Feb 2025 08:41:56 GMT', 'content-type': 'application/json', 'transfer-encoding': 'chunked', 'connection': 'keep-alive', 'access-control-expose-headers': 'X-Request-ID', 'openai-organization': 'user-r8fvvzrst5hfap7jphqbxk6c', 'openai-processing-ms': '2423', 'openai-version': '2020-10-01', 'x-ratelimit-limit-input-images': '50000', 'x-ratelimit-limit-requests': '5000', 'x-ratelimit-limit-tokens': '800000', 'x-ratelimit-remaining-input-images': '49999', 'x-ratelimit-remaining-requests': '4999', 'x-ratelimit-remaining-tokens': '798754', 'x-ratelimit-reset-input-images': '1ms', 'x-ratelimit-reset-requests': '12ms', 'x-ratelimit-reset-tokens': '93ms', 'x-request-id': 'req_f06eb55fb3fcd3a5c0410accfa3a3f6c', 'strict-transport-security': 'max-age=31536000; includeSubDomains; preload', 'cf-cache-status': 'DYNAMIC', 'x-content-type-options': 'nosniff', 'server': 'cloudflare', 'cf-ray': '90ea52b5af3253f1-ATL', 'content-encoding': 'gzip', 'alt-svc': 'h3=":443"; ma=86400'})
[2025-02-08 08:41:56,492] DEBUG in _base_client: request_id: req_f06eb55fb3fcd3a5c0410accfa3a3f6c
[2025-02-08 08:41:56,492] DEBUG in ai_processor: Empty response content from OpenAI
[2025-02-08 08:41:56,492] ERROR in ai_processor: Unexpected error in initial process: no_events_found
[2025-02-08 08:41:56,492] ERROR in routes: Process error: initial_process_failed
Traceback (most recent call last):
  File "/home/runner/workspace/utils/ai_processor.py", line 186, in process_image_and_text
    raise Exception("no_events_found")
Exception: no_events_found

During handling of the above exception, another exception occurred:

Traceback (most recent call last):
  File "/home/runner/workspace/routes.py", line 66, in process
    result = process_image_and_text(image_data, text, None, timezone)
             ^^^^^^^^^^^^^^^^^^^^^^^^^^^^^^^^^^^^^^^^^^^^^^^^^^^^^^^^
  File "/home/runner/workspace/utils/ai_processor.py", line 255, in process_image_and_text
    raise Exception("initial_process_failed")
Exception: initial_process_failed